[ERROR] 2019-11-01 13:50:17,275 | /home/umoms/moms-bench/apps/frappe/frappe/utils/error.py:
New Exception collected with id: 2019-11-01 13:50:17.265109-192.168.2.200-ae5
[ERROR] 2019-11-01 13:50:33,777 | /home/umoms/moms-bench/apps/frappe/frappe/app.py:
Site: moms-site1
Request Error
Traceback (most recent call last):
  File "/home/umoms/moms-bench/apps/frappe/frappe/app.py", line 52, in application
    init_request(request)
  File "/home/umoms/moms-bench/apps/frappe/frappe/app.py", line 117, in init_request
    frappe.local.http_request = frappe.auth.HTTPRequest()
  File "/home/umoms/moms-bench/apps/frappe/frappe/auth.py", line 42, in __init__
    self.set_lang()
  File "/home/umoms/moms-bench/apps/frappe/frappe/auth.py", line 86, in set_lang
    frappe.local.lang = guess_language()
  File "/home/umoms/moms-bench/apps/frappe/frappe/translate.py", line 29, in guess_language
    lang_list = get_all_languages() or []
  File "/home/umoms/moms-bench/apps/frappe/frappe/translate.py", line 85, in get_all_languages
    return frappe.cache().get_value('languages', _get)
  File "/home/umoms/moms-bench/apps/frappe/frappe/utils/redis_wrapper.py", line 79, in get_value
    val = generator()
  File "/home/umoms/moms-bench/apps/frappe/frappe/translate.py", line 84, in _get
    return frappe.db.sql_list('select name from tabLanguage')
  File "/home/umoms/moms-bench/apps/frappe/frappe/database/database.py", line 235, in sql_list
    return [r[0] for r in self.sql(query, values, debug=debug)]
  File "/home/umoms/moms-bench/apps/frappe/frappe/database/database.py", line 122, in sql
    self.connect()
  File "/home/umoms/moms-bench/apps/frappe/frappe/database/database.py", line 75, in connect
    self._conn = self.get_connection()
  File "/home/umoms/moms-bench/apps/frappe/frappe/database/mariadb/database.py", line 90, in get_connection
    local_infile = frappe.conf.local_infile)
  File "/home/umoms/moms-bench/env/local/lib/python2.7/site-packages/pymysql/__init__.py", line 94, in Connect
    return Connection(*args, **kwargs)
  File "/home/umoms/moms-bench/env/local/lib/python2.7/site-packages/pymysql/connections.py", line 325, in __init__
    self.connect()
  File "/home/umoms/moms-bench/env/local/lib/python2.7/site-packages/pymysql/connections.py", line 630, in connect
    raise exc
OperationalError: (2003, "Can't connect to MySQL server on u'localhost' ([Errno 111] Connection refused)")
[ERROR] 2019-11-01 13:50:34,026 | /home/umoms/moms-bench/apps/frappe/frappe/utils/error.py:
New Exception collected with id: 2019-11-01 13:50:33.778736-192.168.2.200-955
[ERROR] 2019-11-01 13:50:34,060 | /home/umoms/moms-bench/apps/frappe/frappe/app.py:
Site: moms-site1
Request Error
Traceback (most recent call last):
  File "/home/umoms/moms-bench/apps/frappe/frappe/app.py", line 52, in application
    init_request(request)
  File "/home/umoms/moms-bench/apps/frappe/frappe/app.py", line 117, in init_request
    frappe.local.http_request = frappe.auth.HTTPRequest()
  File "/home/umoms/moms-bench/apps/frappe/frappe/auth.py", line 42, in __init__
    self.set_lang()
  File "/home/umoms/moms-bench/apps/frappe/frappe/auth.py", line 86, in set_lang
    frappe.local.lang = guess_language()
  File "/home/umoms/moms-bench/apps/frappe/frappe/translate.py", line 29, in guess_language
    lang_list = get_all_languages() or []
  File "/home/umoms/moms-bench/apps/frappe/frappe/translate.py", line 85, in get_all_languages
    return frappe.cache().get_value('languages', _get)
  File "/home/umoms/moms-bench/apps/frappe/frappe/utils/redis_wrapper.py", line 79, in get_value
    val = generator()
  File "/home/umoms/moms-bench/apps/frappe/frappe/translate.py", line 84, in _get
    return frappe.db.sql_list('select name from tabLanguage')
  File "/home/umoms/moms-bench/apps/frappe/frappe/database/database.py", line 235, in sql_list
    return [r[0] for r in self.sql(query, values, debug=debug)]
  File "/home/umoms/moms-bench/apps/frappe/frappe/database/database.py", line 122, in sql
    self.connect()
  File "/home/umoms/moms-bench/apps/frappe/frappe/database/database.py", line 75, in connect
    self._conn = self.get_connection()
  File "/home/umoms/moms-bench/apps/frappe/frappe/database/mariadb/database.py", line 90, in get_connection
    local_infile = frappe.conf.local_infile)
  File "/home/umoms/moms-bench/env/local/lib/python2.7/site-packages/pymysql/__init__.py", line 94, in Connect
    return Connection(*args, **kwargs)
  File "/home/umoms/moms-bench/env/local/lib/python2.7/site-packages/pymysql/connections.py", line 325, in __init__
    self.connect()
  File "/home/umoms/moms-bench/env/local/lib/python2.7/site-packages/pymysql/connections.py", line 630, in connect
    raise exc
OperationalError: (2003, "Can't connect to MySQL server on u'localhost' ([Errno 111] Connection refused)")
[ERROR] 2019-11-01 13:50:34,075 | /home/umoms/moms-bench/apps/frappe/frappe/utils/error.py:
New Exception collected with id: 2019-11-01 13:50:34.061754-192.168.2.200-333
[ERROR] 2019-11-01 15:06:41,770 | /home/umoms/moms-bench/apps/frappe/frappe/app.py:
Site: moms-site1
Request Error
Traceback (most recent call last):
  File "/home/umoms/moms-bench/apps/frappe/frappe/app.py", line 52, in application
    init_request(request)
  File "/home/umoms/moms-bench/apps/frappe/frappe/app.py", line 117, in init_request
    frappe.local.http_request = frappe.auth.HTTPRequest()
  File "/home/umoms/moms-bench/apps/frappe/frappe/auth.py", line 42, in __init__
    self.set_lang()
  File "/home/umoms/moms-bench/apps/frappe/frappe/auth.py", line 86, in set_lang
    frappe.local.lang = guess_language()
  File "/home/umoms/moms-bench/apps/frappe/frappe/translate.py", line 29, in guess_language
    lang_list = get_all_languages() or []
  File "/home/umoms/moms-bench/apps/frappe/frappe/translate.py", line 85, in get_all_languages
    return frappe.cache().get_value('languages', _get)
  File "/home/umoms/moms-bench/apps/frappe/frappe/utils/redis_wrapper.py", line 79, in get_value
    val = generator()
  File "/home/umoms/moms-bench/apps/frappe/frappe/translate.py", line 84, in _get
    return frappe.db.sql_list('select name from tabLanguage')
  File "/home/umoms/moms-bench/apps/frappe/frappe/database/database.py", line 235, in sql_list
    return [r[0] for r in self.sql(query, values, debug=debug)]
  File "/home/umoms/moms-bench/apps/frappe/frappe/database/database.py", line 122, in sql
    self.connect()
  File "/home/umoms/moms-bench/apps/frappe/frappe/database/database.py", line 75, in connect
    self._conn = self.get_connection()
  File "/home/umoms/moms-bench/apps/frappe/frappe/database/mariadb/database.py", line 90, in get_connection
    local_infile = frappe.conf.local_infile)
  File "/home/umoms/moms-bench/env/local/lib/python2.7/site-packages/pymysql/__init__.py", line 94, in Connect
    return Connection(*args, **kwargs)
  File "/home/umoms/moms-bench/env/local/lib/python2.7/site-packages/pymysql/connections.py", line 325, in __init__
    self.connect()
  File "/home/umoms/moms-bench/env/local/lib/python2.7/site-packages/pymysql/connections.py", line 630, in connect
    raise exc
OperationalError: (2003, "Can't connect to MySQL server on u'localhost' ([Errno 111] Connection refused)")
[ERROR] 2019-11-01 15:06:41,789 | /home/umoms/moms-bench/apps/frappe/frappe/utils/error.py:
New Exception collected with id: 2019-11-01 15:06:41.772308-192.168.2.200-6f8
[ERROR] 2019-11-01 15:06:41,814 | /home/umoms/moms-bench/apps/frappe/frappe/app.py:
Site: moms-site1
Request Error
Traceback (most recent call last):
  File "/home/umoms/moms-bench/apps/frappe/frappe/app.py", line 52, in application
    init_request(request)
  File "/home/umoms/moms-bench/apps/frappe/frappe/app.py", line 117, in init_request
    frappe.local.http_request = frappe.auth.HTTPRequest()
  File "/home/umoms/moms-bench/apps/frappe/frappe/auth.py", line 42, in __init__
    self.set_lang()
  File "/home/umoms/moms-bench/apps/frappe/frappe/auth.py", line 86, in set_lang
    frappe.local.lang = guess_language()
  File "/home/umoms/moms-bench/apps/frappe/frappe/translate.py", line 29, in guess_language
    lang_list = get_all_languages() or []
  File "/home/umoms/moms-bench/apps/frappe/frappe/translate.py", line 85, in get_all_languages
    return frappe.cache().get_value('languages', _get)
  File "/home/umoms/moms-bench/apps/frappe/frappe/utils/redis_wrapper.py", line 79, in get_value
    val = generator()
  File "/home/umoms/moms-bench/apps/frappe/frappe/translate.py", line 84, in _get
    return frappe.db.sql_list('select name from tabLanguage')
  File "/home/umoms/moms-bench/apps/frappe/frappe/database/database.py", line 235, in sql_list
    return [r[0] for r in self.sql(query, values, debug=debug)]
  File "/home/umoms/moms-bench/apps/frappe/frappe/database/database.py", line 122, in sql
    self.connect()
  File "/home/umoms/moms-bench/apps/frappe/frappe/database/database.py", line 75, in connect
    self._conn = self.get_connection()
  File "/home/umoms/moms-bench/apps/frappe/frappe/database/mariadb/database.py", line 90, in get_connection
    local_infile = frappe.conf.local_infile)
  File "/home/umoms/moms-bench/env/local/lib/python2.7/site-packages/pymysql/__init__.py", line 94, in Connect
    return Connection(*args, **kwargs)
  File "/home/umoms/moms-bench/env/local/lib/python2.7/site-packages/pymysql/connections.py", line 325, in __init__
    self.connect()
  File "/home/umoms/moms-bench/env/local/lib/python2.7/site-packages/pymysql/connections.py", line 630, in connect
    raise exc
OperationalError: (2003, "Can't connect to MySQL server on u'localhost' ([Errno 111] Connection refused)")
[ERROR] 2019-11-01 15:06:41,832 | /home/umoms/moms-bench/apps/frappe/frappe/utils/error.py:
New Exception collected with id: 2019-11-01 15:06:41.815451-192.168.2.200-5ff
